2020-09-13 08:22:17,053 INFO     Job started for command "detect" with arguments:
2020-09-13 08:22:17,054 INFO         {
2020-09-13 08:22:17,055 INFO             "detectors": [
2020-09-13 08:22:17,056 INFO                 "Old Bird Tseep Detector Redux 1.1"
2020-09-13 08:22:17,057 INFO             ],
2020-09-13 08:22:17,059 INFO             "stations": [
2020-09-13 08:22:17,062 INFO                 "MSGR"
2020-09-13 08:22:17,064 INFO             ],
2020-09-13 08:22:17,065 INFO             "start_date": "2020-09-09",
2020-09-13 08:22:17,066 INFO             "end_date": "2020-09-20",
2020-09-13 08:22:17,067 INFO             "schedule": "",
2020-09-13 08:22:17,067 INFO             "defer_clip_creation": false
2020-09-13 08:22:17,068 INFO         }
2020-09-13 08:22:17,081 INFO     This command will process recordings for 4 station-nights.
2020-09-13 08:22:17,081 INFO     Processing recordings for station-night 1 of 4 - "MSGR 2020-09-09"...
2020-09-13 08:22:17,085 INFO         Processing recording 1 of 1 - "MSGR / PC / start 2020-09-10 00:51:00+00:00 / duration 7.867 h"...
2020-09-13 08:22:17,089 INFO             Running detector on file "/Volumes/Erebus/msgr-vesper-archive/Recordings/MSGR_2020-09-10_00.51.00_Z.wav"...
2020-09-13 08:23:46,005 INFO             Created 2329 clips from detector "Old Bird Tseep Detector Redux 1.1".
2020-09-13 08:23:46,006 INFO             Ran 1 detector on 28320 seconds of 1-channel audio in 89 seconds, 319 times faster than real time.
2020-09-13 08:23:46,054 INFO     Processing recordings for station-night 2 of 4 - "MSGR 2020-09-10"...
2020-09-13 08:23:46,057 INFO         Processing recording 1 of 1 - "MSGR / PC / start 2020-09-11 00:51:00+00:00 / duration 7.867 h"...
2020-09-13 08:23:46,062 INFO             Running detector on file "/Volumes/Erebus/msgr-vesper-archive/Recordings/MSGR_2020-09-11_00.51.00_Z.wav"...
2020-09-13 08:23:46,742 ERROR    Job failed with an exception. See traceback below.
Traceback (most recent call last):
  File "/Users/richard/miniconda3/envs/vesper-0.4.8/lib/python3.6/site-packages/django/db/backends/utils.py", line 86, in _execute
    return self.cursor.execute(sql, params)
  File "/Users/richard/miniconda3/envs/vesper-0.4.8/lib/python3.6/site-packages/django/db/backends/sqlite3/base.py", line 396, in execute
    return Database.Cursor.execute(self, query, params)
sqlite3.IntegrityError: UNIQUE constraint failed: vesper_clip.recording_channel_id, vesper_clip.start_time, vesper_clip.creating_processor_id

The above exception was the direct cause of the following exception:

Traceback (most recent call last):
  File "/Users/richard/miniconda3/envs/vesper-0.4.8/lib/python3.6/site-packages/vesper/command/detect_command.py", line 866, in _create_clips
    creating_processor=detector_model
  File "/Users/richard/miniconda3/envs/vesper-0.4.8/lib/python3.6/site-packages/django/db/models/manager.py", line 82, in manager_method
    return getattr(self.get_queryset(), name)(*args, **kwargs)
  File "/Users/richard/miniconda3/envs/vesper-0.4.8/lib/python3.6/site-packages/django/db/models/query.py", line 433, in create
    obj.save(force_insert=True, using=self.db)
  File "/Users/richard/miniconda3/envs/vesper-0.4.8/lib/python3.6/site-packages/django/db/models/base.py", line 746, in save
    force_update=force_update, update_fields=update_fields)
  File "/Users/richard/miniconda3/envs/vesper-0.4.8/lib/python3.6/site-packages/django/db/models/base.py", line 784, in save_base
    force_update, using, update_fields,
  File "/Users/richard/miniconda3/envs/vesper-0.4.8/lib/python3.6/site-packages/django/db/models/base.py", line 887, in _save_table
    results = self._do_insert(cls._base_manager, using, fields, returning_fields, raw)
  File "/Users/richard/miniconda3/envs/vesper-0.4.8/lib/python3.6/site-packages/django/db/models/base.py", line 926, in _do_insert
    using=using, raw=raw,
  File "/Users/richard/miniconda3/envs/vesper-0.4.8/lib/python3.6/site-packages/django/db/models/manager.py", line 82, in manager_method
    return getattr(self.get_queryset(), name)(*args, **kwargs)
  File "/Users/richard/miniconda3/envs/vesper-0.4.8/lib/python3.6/site-packages/django/db/models/query.py", line 1204, in _insert
    return query.get_compiler(using=using).execute_sql(returning_fields)
  File "/Users/richard/miniconda3/envs/vesper-0.4.8/lib/python3.6/site-packages/django/db/models/sql/compiler.py", line 1391, in execute_sql
    cursor.execute(sql, params)
  File "/Users/richard/miniconda3/envs/vesper-0.4.8/lib/python3.6/site-packages/django/db/backends/utils.py", line 100, in execute
    return super().execute(sql, params)
  File "/Users/richard/miniconda3/envs/vesper-0.4.8/lib/python3.6/site-packages/django/db/backends/utils.py", line 68, in execute
    return self._execute_with_wrappers(sql, params, many=False, executor=self._execute)
  File "/Users/richard/miniconda3/envs/vesper-0.4.8/lib/python3.6/site-packages/django/db/backends/utils.py", line 77, in _execute_with_wrappers
    return executor(sql, params, many, context)
  File "/Users/richard/miniconda3/envs/vesper-0.4.8/lib/python3.6/site-packages/django/db/backends/utils.py", line 86, in _execute
    return self.cursor.execute(sql, params)
  File "/Users/richard/miniconda3/envs/vesper-0.4.8/lib/python3.6/site-packages/django/db/utils.py", line 90, in __exit__
    raise dj_exc_value.with_traceback(traceback) from exc_value
  File "/Users/richard/miniconda3/envs/vesper-0.4.8/lib/python3.6/site-packages/django/db/backends/utils.py", line 86, in _execute
    return self.cursor.execute(sql, params)
  File "/Users/richard/miniconda3/envs/vesper-0.4.8/lib/python3.6/site-packages/django/db/backends/sqlite3/base.py", line 396, in execute
    return Database.Cursor.execute(self, query, params)
django.db.utils.IntegrityError: UNIQUE constraint failed: vesper_clip.recording_channel_id, vesper_clip.start_time, vesper_clip.creating_processor_id

During handling of the above exception, another exception occurred:

Traceback (most recent call last):
  File "/Users/richard/miniconda3/envs/vesper-0.4.8/lib/python3.6/site-packages/django/db/models/fields/related_descriptors.py", line 172, in __get__
    rel_obj = self.field.get_cached_value(instance)
  File "/Users/richard/miniconda3/envs/vesper-0.4.8/lib/python3.6/site-packages/django/db/models/fields/mixins.py", line 13, in get_cached_value
    return instance._state.fields_cache[cache_name]
KeyError: 'device'

During handling of the above exception, another exception occurred:

Traceback (most recent call last):
  File "/Users/richard/miniconda3/envs/vesper-0.4.8/lib/python3.6/site-packages/vesper/command/job_runner.py", line 145, in run_job
    complete = command.execute(info)
  File "/Users/richard/miniconda3/envs/vesper-0.4.8/lib/python3.6/site-packages/vesper/command/detect_command.py", line 152, in execute
    self._run_other_detectors(other_detectors, recordings)
  File "/Users/richard/miniconda3/envs/vesper-0.4.8/lib/python3.6/site-packages/vesper/command/detect_command.py", line 352, in _run_other_detectors
    detector_models, file_, recording_intervals)
  File "/Users/richard/miniconda3/envs/vesper-0.4.8/lib/python3.6/site-packages/vesper/command/detect_command.py", line 438, in _run_other_detectors_on_file
    detector_models, file_, abs_path, reader, interval)
  File "/Users/richard/miniconda3/envs/vesper-0.4.8/lib/python3.6/site-packages/vesper/command/detect_command.py", line 467, in _run_other_detectors_on_file_interval
    detector.detect(channel_samples)
  File "/Users/richard/miniconda3/envs/vesper-0.4.8/lib/python3.6/site-packages/vesper/old_bird/old_bird_detector_redux_1_1.py", line 278, in detect
    self._notify_listener(clips)
  File "/Users/richard/miniconda3/envs/vesper-0.4.8/lib/python3.6/site-packages/vesper/old_bird/old_bird_detector_redux_1_1.py", line 322, in _notify_listener
    self._listener.process_clip(start_index, length)
  File "/Users/richard/miniconda3/envs/vesper-0.4.8/lib/python3.6/site-packages/vesper/command/detect_command.py", line 784, in process_clip
    self._create_clips(threshold)
  File "/Users/richard/miniconda3/envs/vesper-0.4.8/lib/python3.6/site-packages/vesper/command/detect_command.py", line 895, in _create_clips
    station.name, mic_output.name,
  File "/Users/richard/miniconda3/envs/vesper-0.4.8/lib/python3.6/site-packages/vesper/django/app/models.py", line 187, in name
    return self.device.name + ' ' + self.local_name
  File "/Users/richard/miniconda3/envs/vesper-0.4.8/lib/python3.6/site-packages/django/db/models/fields/related_descriptors.py", line 186, in __get__
    rel_obj = self.get_object(instance)
  File "/Users/richard/miniconda3/envs/vesper-0.4.8/lib/python3.6/site-packages/django/db/models/fields/related_descriptors.py", line 153, in get_object
    return qs.get(self.field.get_reverse_related_filter(instance))
  File "/Users/richard/miniconda3/envs/vesper-0.4.8/lib/python3.6/site-packages/django/db/models/query.py", line 411, in get
    num = len(clone)
  File "/Users/richard/miniconda3/envs/vesper-0.4.8/lib/python3.6/site-packages/django/db/models/query.py", line 258, in __len__
    self._fetch_all()
  File "/Users/richard/miniconda3/envs/vesper-0.4.8/lib/python3.6/site-packages/django/db/models/query.py", line 1261, in _fetch_all
    self._result_cache = list(self._iterable_class(self))
  File "/Users/richard/miniconda3/envs/vesper-0.4.8/lib/python3.6/site-packages/django/db/models/query.py", line 57, in __iter__
    results = compiler.execute_sql(chunked_fetch=self.chunked_fetch, chunk_size=self.chunk_size)
  File "/Users/richard/miniconda3/envs/vesper-0.4.8/lib/python3.6/site-packages/django/db/models/sql/compiler.py", line 1151, in execute_sql
    cursor.execute(sql, params)
  File "/Users/richard/miniconda3/envs/vesper-0.4.8/lib/python3.6/site-packages/django/db/backends/utils.py", line 100, in execute
    return super().execute(sql, params)
  File "/Users/richard/miniconda3/envs/vesper-0.4.8/lib/python3.6/site-packages/django/db/backends/utils.py", line 68, in execute
    return self._execute_with_wrappers(sql, params, many=False, executor=self._execute)
  File "/Users/richard/miniconda3/envs/vesper-0.4.8/lib/python3.6/site-packages/django/db/backends/utils.py", line 77, in _execute_with_wrappers
    return executor(sql, params, many, context)
  File "/Users/richard/miniconda3/envs/vesper-0.4.8/lib/python3.6/site-packages/django/db/backends/utils.py", line 80, in _execute
    self.db.validate_no_broken_transaction()
  File "/Users/richard/miniconda3/envs/vesper-0.4.8/lib/python3.6/site-packages/django/db/backends/base/base.py", line 449, in validate_no_broken_transaction
    "An error occurred in the current transaction. You can't "
django.db.transaction.TransactionManagementError: An error occurred in the current transaction. You can't execute queries until the end of the 'atomic' block.

